2019-01-02 23:04:11,502 ERROR: Exception on /login [GET] [in c:\users\simon okello\documents\andela\flask\env\lib\site-packages\flask\app.py:1761]
Traceback (most recent call last):
  File "c:\users\simon okello\documents\andela\flask\env\lib\site-packages\flask\app.py", line 2292, in wsgi_app
    response = self.full_dispatch_request()
  File "c:\users\simon okello\documents\andela\flask\env\lib\site-packages\flask\app.py", line 1815, in full_dispatch_request
    rv = self.handle_user_exception(e)
  File "c:\users\simon okello\documents\andela\flask\env\lib\site-packages\flask\app.py", line 1718, in handle_user_exception
    reraise(exc_type, exc_value, tb)
  File "c:\users\simon okello\documents\andela\flask\env\lib\site-packages\flask\_compat.py", line 35, in reraise
    raise value
  File "c:\users\simon okello\documents\andela\flask\env\lib\site-packages\flask\app.py", line 1813, in full_dispatch_request
    rv = self.dispatch_request()
  File "c:\users\simon okello\documents\andela\flask\env\lib\site-packages\flask\app.py", line 1799, in dispatch_request
    return self.view_functions[rule.endpoint](**req.view_args)
  File "C:\Users\Simon Okello\Documents\ANDELA\Flask\app\routes.py", line 77, in login
    return render_template("login.html", title="Sign In", form=form)
  File "c:\users\simon okello\documents\andela\flask\env\lib\site-packages\flask\templating.py", line 135, in render_template
    context, ctx.app)
  File "c:\users\simon okello\documents\andela\flask\env\lib\site-packages\flask\templating.py", line 117, in _render
    rv = template.render(context)
  File "c:\users\simon okello\documents\andela\flask\env\lib\site-packages\jinja2\asyncsupport.py", line 76, in render
    return original_render(self, *args, **kwargs)
  File "c:\users\simon okello\documents\andela\flask\env\lib\site-packages\jinja2\environment.py", line 1008, in render
    return self.environment.handle_exception(exc_info, True)
  File "c:\users\simon okello\documents\andela\flask\env\lib\site-packages\jinja2\environment.py", line 780, in handle_exception
    reraise(exc_type, exc_value, tb)
  File "c:\users\simon okello\documents\andela\flask\env\lib\site-packages\jinja2\_compat.py", line 37, in reraise
    raise value.with_traceback(tb)
  File "C:\Users\Simon Okello\Documents\ANDELA\Flask\app\templates\login.html", line 1, in top-level template code
    {% extends "layout.html" %}
  File "C:\Users\Simon Okello\Documents\ANDELA\Flask\app\templates\layout.html", line 36, in top-level template code
    {% block content %}
  File "C:\Users\Simon Okello\Documents\ANDELA\Flask\app\templates\login.html", line 29, in block "content"
    <p>Forgot your password <a href="{{url_for('reset_password_request')}}">Click here to reset</a> </p>
  File "c:\users\simon okello\documents\andela\flask\env\lib\site-packages\flask\helpers.py", line 356, in url_for
    return appctx.app.handle_url_build_error(error, endpoint, values)
  File "c:\users\simon okello\documents\andela\flask\env\lib\site-packages\flask\app.py", line 2061, in handle_url_build_error
    reraise(exc_type, exc_value, tb)
  File "c:\users\simon okello\documents\andela\flask\env\lib\site-packages\flask\_compat.py", line 35, in reraise
    raise value
  File "c:\users\simon okello\documents\andela\flask\env\lib\site-packages\flask\helpers.py", line 345, in url_for
    force_external=external)
  File "c:\users\simon okello\documents\andela\flask\env\lib\site-packages\werkzeug\routing.py", line 1776, in build
    raise BuildError(endpoint, values, method, self)
werkzeug.routing.BuildError: Could not build url for endpoint 'reset_password_request'. Did you mean 'edit_profile' instead?
2019-01-02 23:19:42,722 INFO: Flask_Demo startup [in C:\Users\Simon Okello\Documents\ANDELA\Flask\app\__init__.py:46]
2019-01-02 23:48:49,751 INFO: Flask_Demo startup [in C:\Users\Simon Okello\Documents\ANDELA\Flask\app\__init__.py:46]
2019-01-02 23:49:10,426 INFO: Flask_Demo startup [in C:\Users\Simon Okello\Documents\ANDELA\Flask\app\__init__.py:46]
2019-01-02 23:51:49,253 ERROR: Exception on /reset_password_request [POST] [in c:\users\simon okello\documents\andela\flask\env\lib\site-packages\flask\app.py:1761]
Traceback (most recent call last):
  File "c:\users\simon okello\documents\andela\flask\env\lib\site-packages\flask_mail.py", line 492, in send
    message.send(connection)
  File "c:\users\simon okello\documents\andela\flask\env\lib\site-packages\flask_mail.py", line 427, in send
    connection.send(self)
  File "c:\users\simon okello\documents\andela\flask\env\lib\site-packages\flask_mail.py", line 192, in send
    message.rcpt_options)
  File "C:\Users\Simon Okello\AppData\Local\Programs\Python\Python37\lib\smtplib.py", line 852, in sendmail
    self.ehlo_or_helo_if_needed()
  File "C:\Users\Simon Okello\AppData\Local\Programs\Python\Python37\lib\smtplib.py", line 600, in ehlo_or_helo_if_needed
    if not (200 <= self.ehlo()[0] <= 299):
  File "C:\Users\Simon Okello\AppData\Local\Programs\Python\Python37\lib\smtplib.py", line 440, in ehlo
    self.putcmd(self.ehlo_msg, name or self.local_hostname)
  File "C:\Users\Simon Okello\AppData\Local\Programs\Python\Python37\lib\smtplib.py", line 367, in putcmd
    self.send(str)
  File "C:\Users\Simon Okello\AppData\Local\Programs\Python\Python37\lib\smtplib.py", line 359, in send
    raise SMTPServerDisconnected('please run connect() first')
smtplib.SMTPServerDisconnected: please run connect() first

During handling of the above exception, another exception occurred:

Traceback (most recent call last):
  File "c:\users\simon okello\documents\andela\flask\env\lib\site-packages\flask\app.py", line 2292, in wsgi_app
    response = self.full_dispatch_request()
  File "c:\users\simon okello\documents\andela\flask\env\lib\site-packages\flask\app.py", line 1815, in full_dispatch_request
    rv = self.handle_user_exception(e)
  File "c:\users\simon okello\documents\andela\flask\env\lib\site-packages\flask\app.py", line 1718, in handle_user_exception
    reraise(exc_type, exc_value, tb)
  File "c:\users\simon okello\documents\andela\flask\env\lib\site-packages\flask\_compat.py", line 35, in reraise
    raise value
  File "c:\users\simon okello\documents\andela\flask\env\lib\site-packages\flask\app.py", line 1813, in full_dispatch_request
    rv = self.dispatch_request()
  File "c:\users\simon okello\documents\andela\flask\env\lib\site-packages\flask\app.py", line 1799, in dispatch_request
    return self.view_functions[rule.endpoint](**req.view_args)
  File "C:\Users\Simon Okello\Documents\ANDELA\Flask\app\routes.py", line 172, in reset_password_request
    send_password_reset_email(user)
  File "C:\Users\Simon Okello\Documents\ANDELA\Flask\app\email.py", line 21, in send_password_reset_email
    user=user, token=token))
  File "C:\Users\Simon Okello\Documents\ANDELA\Flask\app\email.py", line 10, in send_email
    mail.send(msg)
  File "c:\users\simon okello\documents\andela\flask\env\lib\site-packages\flask_mail.py", line 492, in send
    message.send(connection)
  File "c:\users\simon okello\documents\andela\flask\env\lib\site-packages\flask_mail.py", line 152, in __exit__
    self.host.quit()
  File "C:\Users\Simon Okello\AppData\Local\Programs\Python\Python37\lib\smtplib.py", line 984, in quit
    res = self.docmd("quit")
  File "C:\Users\Simon Okello\AppData\Local\Programs\Python\Python37\lib\smtplib.py", line 420, in docmd
    self.putcmd(cmd, args)
  File "C:\Users\Simon Okello\AppData\Local\Programs\Python\Python37\lib\smtplib.py", line 367, in putcmd
    self.send(str)
  File "C:\Users\Simon Okello\AppData\Local\Programs\Python\Python37\lib\smtplib.py", line 359, in send
    raise SMTPServerDisconnected('please run connect() first')
smtplib.SMTPServerDisconnected: please run connect() first
